<?xml version="1.0" ?>
<robot name="mobile_robot_final" xmlns:xacro="http://www.ros.org/wiki/xacro">

<xacro:include filename="$(find mobile_robot_final_description)/urdf/materials.xacro" />
<xacro:include filename="$(find mobile_robot_final_description)/urdf/mobile_robot_final.trans" />
<xacro:include filename="$(find mobile_robot_final_description)/urdf/mobile_robot_final.gazebo" />
<link name="base_link">
  <inertial>
    <origin xyz="0.0018980536553154037 0.0 0.023812309306618297" rpy="0 0 0"/>
    <mass value="0.2882739103934156"/>
    <inertia ixx="0.000246" iyy="0.000259" izz="0.000462" ixy="-0.0" iyz="-0.0" ixz="-9e-06"/>
  </inertial>
  <visual>
    <origin xyz="0 0 0" rpy="0 0 0"/>
    <geometry>
      <mesh filename="package://mobile_robot_final_description/meshes/base_link.stl" scale="0.001 0.001 0.001"/>
    </geometry>
    <material name="silver"/>
  </visual>
  <collision>
    <origin xyz="0 0 0" rpy="0 0 0"/>
    <geometry>
      <mesh filename="package://mobile_robot_final_description/meshes/base_link.stl" scale="0.001 0.001 0.001"/>
    </geometry>
  </collision>
</link>

<link name="right_wheel_1">
  <inertial>
    <origin xyz="0.0 -0.0050000000000000044 1.862645142292063e-10" rpy="0 0 0"/>
    <mass value="0.014791010912182443"/>
    <inertia ixx="2e-06" iyy="4e-06" izz="2e-06" ixy="-0.0" iyz="0.0" ixz="-0.0"/>
  </inertial>
  <visual>
    <origin xyz="-0.0 0.05 -0.0225" rpy="0 0 0"/>
    <geometry>
      <mesh filename="package://mobile_robot_final_description/meshes/right_wheel_1.stl" scale="0.001 0.001 0.001"/>
    </geometry>
    <material name="silver"/>
  </visual>
  <collision>
    <origin xyz="-0.0 0.05 -0.0225" rpy="0 0 0"/>
    <geometry>
      <mesh filename="package://mobile_robot_final_description/meshes/right_wheel_1.stl" scale="0.001 0.001 0.001"/>
    </geometry>
  </collision>
</link>

<link name="left_wheel_1">
  <inertial>
    <origin xyz="0.0 0.0049999999999999975 1.8626452116810022e-10" rpy="0 0 0"/>
    <mass value="0.014791010912182437"/>
    <inertia ixx="2e-06" iyy="4e-06" izz="2e-06" ixy="0.0" iyz="0.0" ixz="0.0"/>
  </inertial>
  <visual>
    <origin xyz="-0.0 -0.05 -0.0225" rpy="0 0 0"/>
    <geometry>
      <mesh filename="package://mobile_robot_final_description/meshes/left_wheel_1.stl" scale="0.001 0.001 0.001"/>
    </geometry>
    <material name="silver"/>
  </visual>
  <collision>
    <origin xyz="-0.0 -0.05 -0.0225" rpy="0 0 0"/>
    <geometry>
      <mesh filename="package://mobile_robot_final_description/meshes/left_wheel_1.stl" scale="0.001 0.001 0.001"/>
    </geometry>
  </collision>
</link>

<link name="lidar_1">
  <inertial>
    <origin xyz="3.7252902498896567e-10 -1.956511856470959e-18 0.0050000000000000044" rpy="0 0 0"/>
    <mass value="0.009623955221823183"/>
    <inertia ixx="1e-06" iyy="1e-06" izz="1e-06" ixy="-0.0" iyz="-0.0" ixz="-0.0"/>
  </inertial>
  <visual>
    <origin xyz="-0.025 -0.0 -0.049" rpy="0 0 0"/>
    <geometry>
      <mesh filename="package://mobile_robot_final_description/meshes/lidar_1.stl" scale="0.001 0.001 0.001"/>
    </geometry>
    <material name="silver"/>
  </visual>
  <collision>
    <origin xyz="-0.025 -0.0 -0.049" rpy="0 0 0"/>
    <geometry>
      <mesh filename="package://mobile_robot_final_description/meshes/lidar_1.stl" scale="0.001 0.001 0.001"/>
    </geometry>
  </collision>
</link>

<joint name="Revolute 3" type="continuous">
  <origin xyz="0.0 -0.05 0.0225" rpy="0 0 0"/>
  <parent link="base_link"/>
  <child link="right_wheel_1"/>
  <axis xyz="0.0 -1.0 0.0"/>
</joint>

<joint name="Revolute 4" type="continuous">
  <origin xyz="0.0 0.05 0.0225" rpy="0 0 0"/>
  <parent link="base_link"/>
  <child link="left_wheel_1"/>
  <axis xyz="0.0 1.0 0.0"/>
</joint>

<joint name="Rigid 5" type="fixed">
  <origin xyz="0.025 0.0 0.049" rpy="0 0 0"/>
  <parent link="base_link"/>
  <child link="lidar_1"/>
</joint>

</robot>
